<?xml version="1.0" ?>
<robot name="Staubli">
    <link name="base_link">
        <visual>
            <geometry>
                <mesh filename="urdf/model/1.STL"/>
            </geometry>
            <origin  xyz="0 0 -0.375" rpy="0 0 0"/>
            <material name="Red">
                <color rgba="1 0 0 1"/>
            </material>
        </visual>
        <collision>
            <origin xyz="0 0 0" rpy="0 0 0"/>
            <geometry>
                <mesh filename="urdf/model/1.STL"/>
            </geometry>
        </collision>
		<inertial>
			<mass value="4.265"/>
			<inertia ixx="0.022470633" ixy=" 6e-9" ixz="-7.69631e-4" iyy="0.020097086" iyz="0.0" izz="0.016467271"/>
		</inertial>
    </link>

    <link name="link_1">
        <visual>
            <geometry>
                <mesh filename="urdf/model/2.STL"/>
            </geometry>
            <origin rpy="-1.5707963 0 0" xyz="0 0 0"/>
            <material name="Red">
                <color rgba="1 0 0 1"/>
            </material>
        </visual>
        <collision>
            <origin xyz="0 0 0" rpy="0 0 0"/>
            <geometry>
                <mesh filename="urdf/model/2.STL"/>
            </geometry>
        </collision>
		<inertial>
			<mass value="7.23"/>
			<inertia ixx="0.059563381" ixy="4.0196e-5" ixz="1.80065e-4" iyy="0.050678093" iyz="0.010037643" izz="0.037079238"/>
		</inertial>
    </link>
	
	<joint name="Joint_1" type="continuous">
        <parent link="base_link"/>
        <child link="link_1"/>
        <origin xyz="0 0 0" rpy="0 0 0"/>
        <axis xyz="0 0 1"/>
        <limit effort="300" velocity="0.01" lower="-2.96" upper="2.96"/>
        <dynamics damping="50" friction="1"/>
    </joint>
</robot>